<?xml version="1.0" ?>
<robot name="KneedCompassGait">

  <!-- x, z, rot-->
  <link name="base"/>
  <link name="base_x"/>
  <link name="base_xz"/>

  <joint name="planar_x" type="prismatic">
    <parent link="base"/>
    <child link="base_x"/>
    <axis xyz="1 0 0"/>
  </joint>
  <joint name="planar_z" type="prismatic">
    <parent link="base_x"/>
    <child link="base_xz"/>
    <axis xyz="0 0 1"/>
  </joint>
  <joint name="planar_roty" type="continuous">
    <parent link="base_xz"/>
    <child link="torso"/>
    <axis xyz="0 -1 0"/>
  </joint>

  <!-- head -->
  <!-- <link name="head_mass">
    <inertial>
      <mass value="50"/>
      <inertia ixx="4" ixy="0" ixz="0" iyy="4" iyz="0" izz="4"/>
    </inertial>
    <visual>
      <geometry>
        <sphere radius="0.075"/>
      </geometry>
      <material name="white">
        <color rgba="1 1 1 1"/>
      </material>
    </visual>
  </link>
  <link name="head">
    <visual>
      <origin xyz="0 0 0.9"/>
      <geometry>
        <cylinder length="0.2" radius="0.005"/>
      </geometry>
      <material name="white">
        <color rgba="1 1 1 1"/>
      </material>
    </visual>
  </link>
  <joint name="head_mass_weld" type="fixed">
    <parent link="head"/>
    <child link="head_mass"/>
    <origin xyz="0 0 1.0"/>
  </joint> -->

  <!-- head & torso -->
  <!-- <joint name="torso_head_weld" type="fixed">
    <parent link="torso"/>
    <child link="head"/>
  </joint> -->

  <!-- torso -->
  <link name="torso_mass">
    <inertial>
      <mass value="50"/>
      <inertia ixx="4" ixy="0" ixz="0" iyy="4" iyz="0" izz="4"/>
    </inertial>
    <visual>
      <geometry>
        <sphere radius="0.075"/>
      </geometry>
      <material name="green">
        <color rgba="0 1 0 1"/>
      </material>
    </visual>
  </link>
  <link name="torso">
    <visual>
      <origin xyz="0 0 0.3"/>
      <geometry>
        <cylinder length="0.6" radius="0.005"/>
      </geometry>
      <material name="green">
        <color rgba="0 1 0 1"/>
      </material>
    </visual>
  </link>
  <joint name="torso_mass_weld" type="fixed">
    <parent link="torso"/>
    <child link="torso_mass"/>
    <origin xyz="0 0 0.3"/>
  </joint>

  <!-- head & left uppper arm -->
  <joint name="left_shoulder_pin" type="continuous">
    <parent link="torso"/>
    <child link="left_upper_arm"/>
    <origin xyz="0 0 0.6" rpy="3.14159 0 0"/>
    <axis xyz="0 1 0"/>
    <limit effort="500"/>
  </joint>

  <!-- left upper arm -->
  <link name="left_upper_arm">
    <visual>
      <origin xyz="0 0 0.2"/>
      <geometry>
        <cylinder length="0.4" radius="0.0075"/>
      </geometry>
      <material name="orange">
          <color rgba="1 0.5 0 1"/>
      </material>
    </visual>
  </link>
  <link name="left_upper_arm_mass">
    <visual>
      <origin xyz="0 0 0.2"/>
      <geometry>
        <sphere radius="0.025"/>
      </geometry>
      <material name="orange">
          <color rgba="1 0.5 0 1"/>
      </material>
    </visual>
    <inertial>
      <origin xyz="0 0 0.2"/>
      <mass value="1.5"/>
      <inertia ixx="0" ixy="0" ixz="0" iyy="0" iyz="0" izz="0"/>
    </inertial>
  </link>
  <joint name="left_upper_arm_mass_weld" type="fixed">
    <parent link="left_upper_arm"/>
    <child link="left_upper_arm_mass"/>
  </joint>

  <!-- left upper & lower arm -->
  <joint name="left_elbow_pin" type="continuous">
    <parent link="left_upper_arm"/>
    <child link="left_lower_arm"/>
    <axis xyz="0 1 0"/>
    <origin xyz="0 0 0.4"/>
    <limit effort="400" lower="0"/>
    <dynamics damping="1" />
  </joint>

  <!-- left lower  -->
  <link name="left_lower_arm">
    <visual>
      <origin xyz="0 0 0.2"/>
      <geometry>
        <cylinder length="0.4" radius="0.0075"/>
      </geometry>
      <material name="orange">
          <color rgba="1 0.5 0 1"/>
      </material>
    </visual>
    <collision>
      <origin xyz="0 0 0.2"/>
      <geometry>
        <sphere radius="0"/>
      </geometry>
    </collision>
  </link>
  <link name="left_lower_arm_mass">
    <visual>
      <origin xyz="0 0 0.2"/>
      <geometry>
        <sphere radius="0.025"/>
      </geometry>
      <material name="orange">
          <color rgba="1 0.5 0 1"/>
      </material>
    </visual>
    <inertial>
      <origin xyz="0 0 0.2"/>
      <mass value="0.5"/>
      <inertia ixx="0" ixy="0" ixz="0" iyy="0" iyz="0" izz="0"/>
    </inertial>
  </link>
  <joint name="left_lower_arm_mass_weld" type="fixed">
    <parent link="left_lower_arm"/>
    <child link="left_lower_arm_mass"/>
  </joint>

  <!-- head & right uppper arm -->
  <joint name="right_shoulder_pin" type="continuous">
    <parent link="torso"/>
    <child link="right_upper_arm"/>
    <origin xyz="0 0 0.6" rpy="3.14159 0 0"/>
    <axis xyz="0 1 0"/>
    <limit effort="500"/>
  </joint>

  <!-- right upper arm -->
  <link name="right_upper_arm">
    <visual>
      <origin xyz="0 0 0.2"/>
      <geometry>
        <cylinder length="0.4" radius="0.0075"/>
      </geometry>
      <material name="yellow">
          <color rgba="1 1 0 1"/>
      </material>
    </visual>
  </link>
  <link name="right_upper_arm_mass">
    <visual>
      <origin xyz="0 0 0.2"/>
      <geometry>
        <sphere radius="0.025"/>
      </geometry>
      <material name="yellow">
          <color rgba="1 1 0 1"/>
      </material>
    </visual>
    <inertial>
      <origin xyz="0 0 0.2"/>
      <mass value="1.5"/>
      <inertia ixx="0" ixy="0" ixz="0" iyy="0" iyz="0" izz="0"/>
    </inertial>
  </link>
  <joint name="right_upper_arm_mass_weld" type="fixed">
    <parent link="right_upper_arm"/>
    <child link="right_upper_arm_mass"/>
  </joint>

  <!-- right upper & lower arm -->
  <joint name="right_elbow_pin" type="continuous">
    <parent link="right_upper_arm"/>
    <child link="right_lower_arm"/>
    <axis xyz="0 1 0"/>
    <origin xyz="0 0 0.4"/>
    <limit effort="400" lower="0"/>
    <dynamics damping="1" />
  </joint>

  <!-- right lower  -->
  <link name="right_lower_arm">
    <visual>
      <origin xyz="0 0 0.2"/>
      <geometry>
        <cylinder length="0.4" radius="0.0075"/>
      </geometry>
      <material name="yellow">
          <color rgba="1 1 0 1"/>
      </material>
    </visual>
    <collision>
      <origin xyz="0 0 0.2"/>
      <geometry>
        <sphere radius="0"/>
      </geometry>
    </collision>
  </link>
  <link name="right_lower_arm_mass">
    <visual>
      <origin xyz="0 0 0.2"/>
      <geometry>
        <sphere radius="0.025"/>
      </geometry>
      <material name="yellow">
          <color rgba="1 1 0 1"/>
      </material>
    </visual>
    <inertial>
      <origin xyz="0 0 0.2"/>
      <mass value="0.5"/>
      <inertia ixx="0" ixy="0" ixz="0" iyy="0" iyz="0" izz="0"/>
    </inertial>
  </link>
  <joint name="right_lower_arm_mass_weld" type="fixed">
    <parent link="right_lower_arm"/>
    <child link="right_lower_arm_mass"/>
  </joint>

  <!-- torso & left uppper leg -->
  <joint name="left_hip_pin" type="continuous">
    <parent link="torso"/>
    <child link="left_upper_leg"/>
    <axis xyz="0 1 0"/>
    <limit effort="500"/>
  </joint>

  <!-- left upper leg-->
  <link name="left_upper_leg">
    <visual>
      <origin xyz="0 0 -0.25"/>
      <geometry>
        <cylinder length="0.5" radius="0.0075"/>
      </geometry>
      <material name="red">
        <color rgba="1 0 0 1"/>
      </material>
    </visual>
  </link>
  <link name="left_upper_leg_mass">
    <visual>
      <origin xyz="0 0 -0.25"/>
      <geometry>
        <sphere radius="0.025"/>
      </geometry>
      <material name="red">
        <color rgba="1 0 0 1"/>
      </material>
    </visual>
    <inertial>
      <origin xyz="0 0 -0.25"/>
      <mass value="1.5"/>
      <inertia ixx="0" ixy="0" ixz="0" iyy="0" iyz="0" izz="0"/>
    </inertial>
  </link>
  <joint name="left_upper_leg_mass_weld" type="fixed">
    <parent link="left_upper_leg"/>
    <child link="left_upper_leg_mass"/>
  </joint>

  <!-- left upper & lower leg -->
  <joint name="left_knee_pin" type="continuous">
    <parent link="left_upper_leg"/>
    <child link="left_lower_leg"/>
    <axis xyz="0 1 0"/>
    <origin xyz="0 0 -0.5"/>
    <limit effort="400" lower="0"/>
    <dynamics damping="1" />
  </joint>

  <!-- left lower leg -->
  <link name="left_lower_leg">
    <visual>
      <origin xyz="0 0 -0.25"/>
      <geometry>
        <cylinder length="0.5" radius="0.0075"/>
      </geometry>
      <material name="red">
        <color rgba="1 0 0 1"/>
      </material>
    </visual>
    <collision>
      <origin xyz="0 0 -0.5"/>
      <geometry>
        <sphere radius="0"/>
      </geometry>
    </collision>
  </link>
  <link name="left_lower_leg_mass">
    <visual>
      <origin xyz="0 0 -0.25"/>
      <geometry>
        <sphere radius="0.025"/>
      </geometry>
      <material name="red">
        <color rgba="1 0 0 1"/>
      </material>
    </visual>
    <inertial>
      <origin xyz="0 0 -0.25"/>
      <mass value="0.5"/>
      <inertia ixx="0" ixy="0" ixz="0" iyy="0" iyz="0" izz="0"/>
    </inertial>
  </link>
  <joint name="left_lower_leg_mass_weld" type="fixed">
    <parent link="left_lower_leg"/>
    <child link="left_lower_leg_mass"/>
  </joint>

  <!-- torso & right uppper leg -->
  <joint name="right_hip_pin" type="continuous">
    <parent link="torso"/>
    <child link="right_upper_leg"/>
    <axis xyz="0 1 0"/>
    <limit effort="500"/>
  </joint>

  <!-- right upper leg -->
  <link name="right_upper_leg">
    <visual>
      <origin xyz="0 0 -0.25"/>
      <geometry>
        <cylinder length="0.5" radius="0.0075"/>
      </geometry>
      <material name="blue">
        <color rgba="0 0 1 1"/>
      </material>
    </visual>
  </link>
  <link name="right_upper_leg_mass">
    <visual>
      <origin xyz="0 0 -0.25"/>
      <geometry>
        <sphere radius="0.025"/>
      </geometry>
      <material name="blue">
        <color rgba="0 0 1 1"/>
      </material>
    </visual>
    <inertial>
      <origin xyz="0 0 -0.25"/>
      <mass value="1.5"/>
      <inertia ixx="0" ixy="0" ixz="0" iyy="0" iyz="0" izz="0"/>
    </inertial>
  </link>
  <joint name="right_upper_leg_mass_weld" type="fixed">
    <parent link="right_upper_leg"/>
    <child link="right_upper_leg_mass"/>
  </joint>

  <!-- right upper & lower leg -->
  <joint name="right_knee_pin" type="revolute">
    <parent link="right_upper_leg"/>
    <child link="right_lower_leg"/>
    <axis xyz="0 1 0"/>
    <origin xyz="0 0 -0.5"/>
    <limit effort="400" lower="0"/>
    <dynamics damping="1" />
  </joint>

  <!-- right lower leg -->
  <link name="right_lower_leg">
    <visual>
      <origin xyz="0 0 -0.25"/>
      <geometry>
        <cylinder length="0.5" radius="0.0075"/>
      </geometry>
      <material name="blue">
        <color rgba="0 0 1 1"/>
      </material>
    </visual>
    <collision>
      <origin xyz="0 0 -0.5"/>
      <geometry>
        <sphere radius="0"/>
      </geometry>
    </collision>
  </link>
  <link name="right_lower_leg_mass">
    <visual>
      <origin xyz="0 0 -0.25"/>
      <geometry>
        <sphere radius="0.025"/>
      </geometry>
      <material name="blue">
        <color rgba="0 0 1 1"/>
      </material>
    </visual>
    <inertial>
      <origin xyz="0 0 -0.25"/>
      <mass value="0.5"/>
      <inertia ixx="0" ixy="0" ixz="0" iyy="0" iyz="0" izz="0"/>
    </inertial>
  </link>
  <joint name="right_lower_leg_mass_weld" type="fixed">
    <parent link="right_lower_leg"/>
    <child link="right_lower_leg_mass"/>
  </joint>

  <!-- transmission -->
  <transmission name="left_hip_trans" type="SimpleTransmission">
    <actuator name="left_hip_torque"/>
    <joint name="left_hip_pin"/>
    <mechanicalReduction>1</mechanicalReduction>
  </transmission>
  <transmission name="right_hip_trans" type="SimpleTransmission">
    <actuator name="right_hip_torque"/>
    <joint name="right_hip_pin"/>
    <mechanicalReduction>1</mechanicalReduction>
  </transmission>
  <transmission name="left_knee_trans" type="SimpleTransmission">
    <actuator name="left_knee_torque"/>
    <joint name="left_knee_pin"/>
    <mechanicalReduction>1</mechanicalReduction>
  </transmission>
  <transmission name="right_knee_trans" type="SimpleTransmission">
    <actuator name="right_knee_torque"/>
    <joint name="right_knee_pin"/>
    <mechanicalReduction>1</mechanicalReduction>
  </transmission>

  <transmission name="left_shoulder_trans" type="SimpleTransmission">
    <actuator name="left_shoulder_torque"/>
    <joint name="left_shoulder_pin"/>
    <mechanicalReduction>1</mechanicalReduction>
  </transmission>
  <transmission name="right_shoulder_trans" type="SimpleTransmission">
    <actuator name="right_shoulder_torque"/>
    <joint name="right_shoulder_pin"/>
    <mechanicalReduction>1</mechanicalReduction>
  </transmission>
  <transmission name="left_elbow_trans" type="SimpleTransmission">
    <actuator name="left_elbow_torque"/>
    <joint name="left_elbow_pin"/>
    <mechanicalReduction>1</mechanicalReduction>
  </transmission>
  <transmission name="right_elbow_trans" type="SimpleTransmission">
    <actuator name="right_elbow_torque"/>
    <joint name="right_elbow_pin"/>
    <mechanicalReduction>1</mechanicalReduction>
  </transmission>

  <!-- collision -->
  <collision_filter_group name="robot_links">
    <member link="left_lower_leg_mass"/>
    <member link="right_lower_leg_mass"/>
    <member link="left_lower_leg"/>
    <member link="right_lower_leg"/>
    <member link="right_upper_leg"/>
    <member link="left_upper_leg"/>

    <member link="left_lower_arm_mass"/>
    <member link="right_lower_arm_mass"/>
    <member link="left_lower_arm"/>
    <member link="right_lower_arm"/>
    <member link="right_upper_arm"/>
    <member link="left_upper_arm"/>

    <member link="torso"/>
    <member link="torso_mass"/>
    <ignored_collision_filter_group collision_filter_group="robot_links"/>
  </collision_filter_group>
</robot>